Workbook

Sheet TPLM
A6: 2024 | B6: Ödeme Teminat Tablosu | F6: Alınan
C7: Tutar | D7: Ödeme | E7: Kalan | F7: Teminat
A8: SnyA | B8: Yıkamacı samed | C8: ='SnyA105-25'!E4 -> 577119.77 | D8: ='SnyA105-25'!F4 -> 0 | E8: =C8-D8 -> 577119.77 | F8: ='SnyA105-25'!E6 -> 0
A9: SnyB | B9: Motorcu salih | C9: ='SnyB202-25'!D4 -> 353664 | D9: ='SnyB202-25'!E4 -> 290000 | E9: =C9-D9 -> 63664 | F9: ='SnyB202-25'!D6 -> -1225.58
A10: SnyCD | B10: Hurdacı ali | C10: ='SnyC301-25'!E4 -> 240000 | D10: ='SnyC301-25'!F4 -> 135000 | E10: =C10-D10 -> 105000 | F10: ='SnyC301-25'!E6 -> -4079.59
A11: SnyE | B11: Motorcu cihan | C11: ='SnyE502-22'!D4 -> 7000 | D11: ='SnyE502-22'!E4 -> 0 | E11: =C11-D11 -> 7000 | F11: ='SnyE502-22'!D6 -> -794.6
A12: SnyF | B12: Demirci merdal | C12: ='SnyF601-22'!E4 -> 447218.54 | D12: ='SnyF601-22'!F4 -> 184917.52 | E12: =C12-D12 -> 262301.02 | F12: ='SnyF601-22'!E6 -> -2824.53
A13: SnyG | B13: Motorcu Metin | C13: ='SnyG702-22'!E4 -> 110513 | D13: ='SnyG702-22'!F4 -> 0 | E13: =C13-D13 -> 110513 | F13: ='SnyG702-22'!E6 -> -1200
A14: SnyH | B14: Yazıhane | C14: =SnH_yazıhane!F2*-1 -> -3999.1 | D14: =C14 -> -3999.1 | E14: =C14-D14 -> 0
B16: Toplamlar | C16: =SUM(C8:C14) -> 1731516.2 | D16: =SUM(D8:D14) -> 605918.42 | E16: =SUM(E8:E14) -> 1125597.8 | F16: =SUM(F8:F14) -> -10124.3
A19: 2025 | B19: Ödeme Teminat Tablosu | F19: Alınan
C20: Tutar | D20: Ödeme | E20: Kalan | F20: Teminat
A21: SnyA | B21: Yıkamacı samed | C21: 150 | D21: 0 | E21: =C21-D21 -> 150 | F21: ='SnyA105-25'!E20 -> 0
A22: SnyB | B22: Motorcu salih | C22: 250 | D22: 0 | E22: =C22-D22 -> 250 | F22: ='SnyB202-25'!D19 -> 0
A23: SnyC | C23: 170 | D23: ='snyc301-25'!#ref! -> #VALUE! | E23: =C23-D23 -> #VALUE! | F23: ='snyc301-25'!#ref! -> #VALUE!
A24: SnyD | C24: 170 | D24: 0 | E24: =C24-D24 -> 170
A25: SnyE | B25: Motorcu cihan | C25: 170 | D25: ='SnyE502-22'!E17 -> 0 | E25: =C25-D25 -> 170 | F25: ='SnyE502-22'!D19 -> 0
A26: SnyF | B26: Demirci merdal | C26: 170 | D26: ='SnyF601-22'!F17 -> 0 | E26: =C26-D26 -> 170 | F26: ='snyf601-22'!#ref! -> #VALUE!
A27: SnyG | B27: Motorcu Metin | C27: 170 | D27: ='SnyG702-22'!F17 -> 0 | E27: =C27-D27 -> 170 | F27: ='SnyG702-22'!E19 -> 0
A28: SnyH | B28: Yazıhane | C28: =SnH_yazıhane!F15*-1 -> 0 | D28: =C28 -> 0 | E28: =C28-D28 -> 0
B30: Toplamlar | C30: =SUM(C21:C28) -> 1250 | D30: =SUM(D21:D28) -> #VALUE! | E30: =SUM(E21:E28) -> #VALUE! | F30: =SUM(F21:F28) -> #VALUE!

Sheet SnyA105-25
B1: snA-086-20230930-080-samedTURGUT | G1: 55 m2 Boya
A3: Tarih | B3: Açıklama | E3: Kira bedeli | F3: Ödeme | G3: Bakiye
B4: Toplamlar | E4: =SUM(E10:E21) -> 577119.77 | F4: =SUM(F10:F21) -> 0 | G4: =G21 -> 577119.77
B5: Masraf | E5: =G41 -> 0
B6: Teminat | E6: =G38 -> 0
F7: NET | G7: =F4-E5 -> 0
B8: ,
A9: 45197 | B9: 30-09-2023 – 31-09-2024 | E9: 84000 | F9: 84000
A10: 45563 | B10: 30-09-2024 – 31-09-2025 | C10: ÖDEME YAPILMADI | E10: =D49 -> 137314.8 | G10: =E10-F10 -> 137314.8
A11: 45928 | B11: 30-09-2025 – 31-09-2026 | C11: ÖDEME YAPILMADI | E11: =D46 -> 189988.76 | G11: =E11-F11+G10 -> 327303.56
A12: 46293 | B12: 30-09-2025 – 31-09-2026 | C12: ÖDEME YAPILMADI | E12: =D43 -> 249816.22 | G12: =E12-F12+G11 -> 577119.77
G13: =E13-F13+G12 -> 577119.77
B14: 45739 | G14: =E14-F14+G13 -> 577119.77
B15: 46302 | G15: =E15-F15+G14 -> 577119.77
G16: =E16-F16+G15 -> 577119.77
G17: =E17-F17+G16 -> 577119.77
G18: =E18-F18+G17 -> 577119.77
G19: =E19-F19+G18 -> 577119.77
G20: =E20-F20+G19 -> 577119.77
G21: =E21-F21+G20 -> 577119.77
A24: - 2023 - | B24: ELEKTRİK (kendi abonesi var) | D24: Su (ödenmiş yazar) | E24: Tutarı | G24: ( 0 TL )
A25: 44927 | B25: Devreden Teminat | D25: 2137.3 | G25: 0
A26: Ocak | B26: 200 TL su alımı 08-01-24 | C26: 24.8 | D26: =D25+C26 -> 2162.1 | G26: =E26-F26+G25 -> 0
A27: Şubat | B27: ortak hesaptan ödeme 08-01-24 | C27: -21.12 | D27: =D26+C27 -> 2140.98 | G27: =E27-F27+G26 -> 0
A28: Mart | B28: ortak hesaptan ödeme 18-03-24 | C28: -52.17 | D28: 2231.5 | G28: =E28-F28+G27 -> 0
A29: Nisan | G29: =E29-F29+G28 -> 0
A30: Mayıs | G30: =E30-F30+G29 -> 0
A31: Haziran | G31: =E31-F31+G30 -> 0
A32: Temmuz | G32: =E32-F32+G31 -> 0
A33: Ağustos | G33: =E33-F33+G32 -> 0
A34: Eylül | G34: =E34-F34+G33 -> 0
A35: Ekim | G35: =E35-F35+G34 -> 0
A36: Kasım | G36: =E36-F36+G35 -> 0
A37: Aralık | G37: =E37-F37+G36 -> 0
A38: 45291 | B38: Devreden Teminat | G38: =E38-F38+G37 -> 0
A41: snyA | B41: Açıklamalar-Masraflar | G41: =SUM(F42:F43) -> 0
C43: =D46 -> 189988.76 | D43: =D44+C43 -> 249816.22
A44: 46295 | B44: 2027 kirası | C44: 31.49 | D44: =C43*C44/100 -> 59827.46
C46: =D49 -> 137314.8 | D46: =D47+C46 -> 189988.76
A47: 45930 | B47: 2026 kirası | C47: 38.36 | D47: =C46*C47/100 -> 52673.957
...

Sheet SnyB202-25
B1: SnyB203-22 | D1: 200 m2 Karo kira
A3: Tarih | B3: Açıklama | D3: Kira bedeli | E3: Ödeme | F3: Bakiye
B4: Toplamlar | D4: =SUM(D9:D20) -> 353664 | E4: =SUM(E9:E20) -> 290000 | F4: =F20 -> 63664
B5: Masraf | D5: =F42 -> 0
B6: Teminat | D6: =F39 -> -1225.58
E7: NET | F7: =E4-D5 -> 290000
B8: ,
A9: - 2025 - | B9: 1-1-25 * 31-12-2025 | F9: =D9-E9 -> 0
B10: 16 * 22 104 KİRA BEDELİ | D10: 353664 | F10: =D10-E10+F9 -> 353664
B11: BANKA ÖDEMESİ | E11: 290000 | F11: =D11-E11+F10 -> 63664
F12: =D12-E12+F11 -> 63664
F13: =D13-E13+F12 -> 63664
B14: 45739 | F14: =D14-E14+F13 -> 63664
F15: =D15-E15+F14 -> 63664
F16: =D16-E16+F15 -> 63664
F17: =D17-E17+F16 -> 63664
F18: =D18-E18+F17 -> 63664
F19: =D19-E19+F18 -> 63664
F20: =D20-E20+F19 -> 63664
A21: 08/01/2024-15:58:33 | B21: 08/01/2024 | D21: 24000
B22: SALİH ANT*0111*2024 yılı iş yeri kira bedeli*1307883986*FAST
B23: 15800126861620240108155833647
A25: - 2023 - | B25: ELEKTRİK | C25: Su | D25: Tutarı | F25: 1600
B26: Devreden Teminat | F26: -1000.12
B27: Su-Elektrik Ocak | C27: 0 | D27: 900.36 | E27: 999.4 | F27: =D27-E27+F26 -> -1099.16
B28: Su-Elektrik Şubat | C28: 0 | D28: 841.46 | E28: 967.88 | F28: =D28-E28+F27 -> -1225.58
B29: Su-Elektrik art | F29: =D29-E29+F28 -> -1225.58
B30: Su-Elektrik Nisan | F30: =D30-E30+F29 -> -1225.58
B31: Su-Elektrik Mayıs | F31: =D31-E31+F30 -> -1225.58
B32: Su-Elektrik Haziran | F32: =D32-E32+F31 -> -1225.58
B33: Su-Elektrik Temmuz | F33: =D33-E33+F32 -> -1225.58
B34: Su-Elektrik Ağustos | F34: =D34-E34+F33 -> -1225.58
B35: Su-Elektrik Eylül | F35: =D35-E35+F34 -> -1225.58
B36: Su-Elektrik Ekim | F36: =D36-E36+F35 -> -1225.58
B37: Su-Elektrik Kasım | F37: =D37-E37+F36 -> -1225.58
B38: Su-Elektrik Aralık | F38: =D38-E38+F37 -> -1225.58
A39: 45291 | B39: Devreden Teminat | C39: =SUM(C27:C38) -> 0 | F39: =D39-E39+F38 -> -1225.58
F40: KALAN
A42: snyB | B42: Açıklamalar-Masraflar | F42: =SUM(F43:F44) -> 0
B46: Salih Ant - 3.yıl
...

Sheet SnyC301-25
B1: snCD-080-03-2211-Vinc | E1: 400 m2 Vinç kira
A3: Tarih | B3: Açıklama | C3: Tüfe % | E3: Kira bedeli | F3: Ödeme | G3: Bakiye
B4: Toplamlar | E4: =SUM(E9:E13) -> 240000 | F4: =SUM(F9:F13) -> 135000 | G4: =#ref! -> #NAME?
B5: Masraf | E5: =G44 -> 161160
B6: Teminat | E6: =G41 -> -4079.59
F7: NET | G7: =F4-E5 -> -26160
B8: Tahliye için icraya başvuruldu
A9: 45259 | G9: =E9-F9 -> 0
D10: =C10*E9 -> 0 | E10: =D10+E9 -> 0 | G10: =E10-F10+G9 -> 0
A11: - 2024 - | B11: 30-11-23 * 29-11-24 | E11: 240000 | G11: =E11-F11+G10 -> 240000
B12: Ödeme Umuta bankadan | F12: 135000 | G12: =E12-F12+G11 -> 105000
G13: =E13-F13+G12 -> 105000
G14: =E14-F14+G13 -> 105000
G15: =E15-F15+G14 -> 105000
A16: - 2025 - | B16: 30-11-23 * 29-11-24 | C16: 24 | D16: 22104 | E16: =D16*C16 -> 530496 | G16: =E16-F16+G15 -> 635496
B17: Ödeme Umuta bankadan | F17: 219000 | G17: =E17-F17+G16 -> 416496
G18: =E18-F18+G17 -> 416496
B19: 45739 | G19: =E19-F19+G18 -> 416496
A28: - 2023 - | B28: ELEKTRİK | D28: Su | E28: Tutarı | G28: 3000
B29: Devreden Teminat | G29: -3924.11
B30: Su-Elektrik Ocak | D30: 0 | E30: 875.64 | F30: 875.64 | G30: =E30-F30+G29 -> -3924.11
B31: Su-Elektrik Şubat | D31: 0 | E31: 1036.52 | F31: 1192 | G31: =E31-F31+G30 -> -4079.59
B32: Su-Elektrik art | G32: =E32-F32+G31 -> -4079.59
B33: Su-Elektrik Nisan | G33: =E33-F33+G32 -> -4079.59
B34: Su-Elektrik Mayıs | G34: =E34-F34+G33 -> -4079.59
B35: Su-Elektrik Haziran | G35: =E35-F35+G34 -> -4079.59
B36: Su-Elektrik Temmuz | G36: =E36-F36+G35 -> -4079.59
B37: Su-Elektrik Ağustos | G37: =E37-F37+G36 -> -4079.59
B38: Su-Elektrik Eylül | G38: =E38-F38+G37 -> -4079.59
B39: Su-Elektrik Ekim | G39: =E39-F39+G38 -> -4079.59
B40: Su-Elektrik Kasım | G40: =E40-F40+G39 -> -4079.59
B41: Su-Elektrik Aralık | G41: =E41-F41+G40 -> -4079.59
A42: 45291 | B42: Devreden Teminat | D42: =SUM(D30:D41) -> 0 | G42: =E42-F42+G41 -> -4079.59
A44: snyCD | B44: Açıklamalar-Masraflar | G44: =SUM(F45:F49) -> 161160
B46: Ali Demirel - 4. yıl
B47: 20-21 kira bedeli 36000 TL Ödendi | D47: 3000 | E47: 12 | F47: =E47*D47 -> 36000 | H47: 36000
B48: 21-22 kira bedeli 43160 TL Ödendi | D48: =F48/E48 -> 3596.6667 | E48: 12 | F48: 43160 | H48: 43160
B49: 22-23 kira bedeli 82000 TL Ödendi | D49: =F49/E49 -> 6833.3333 | E49: 12 | F49: 82000 | H49: 82000
B50: 23-24 bedel 240000 TL | H50: 135000
B51: 24-25 bedel 530000 TL
...

Sheet SnyCD-HSP-2025
B1: - 2024 - 2025
A3: SNYCD-HESAP | F3: =SUM(F7:F65) -> 1041691.3 | G3: =SUM(G7:G65) -> 655000 | H3: =F3-G3 -> 386691.33
C4: Tüfe | E4: kira tüfe farkı
A5: Tarih | B5: Açıklama | C5: Endeks | D5: % | E5: Bedel | F5: bedel | G5: Ödeme | H5: Bakiye
H6: =H7+F6-G6 -> 386691.33
H7: =H8+F7-G7 -> 386691.33
H8: =H9+F8-G8 -> 386691.33
H9: =H10+F9-G9 -> 386691.33
H10: =H11+F10-G10 -> 386691.33
H11: =H12+F11-G11 -> 386691.33
H12: =H13+F12-G12 -> 386691.33
H13: =H14+F13-G13 -> 386691.33
H14: =H15+F14-G14 -> 386691.33
H15: =H16+F15-G15 -> 386691.33
H16: =H17+F16-G16 -> 386691.33
B17: 46012 | H17: =H18+F17-G17 -> 386691.33
A18: 45991 | B18: ödeme | G18: 301000 | H18: =H19+F18-G18 -> 386691.33
A19: 45991 | B19: tüfe 2024-12 | C19: 2684.55 | D19: 0.35 | E19: =F20*D19 -> 185673.6 | F19: =IF(H20<=0,,(H20*D19)) -> 178290.34 | H19: =H20+F19-G19 -> 687691.33
B20: 2025 - 12 ay | E20: =E24 -> 530496 | F20: =E20 -> 530496 | H20: =H21+F20-G20 -> 509400.98
B21: dava rededildi karşı avukat ücreti | F21: 22000 | H21: =H22+F21-G21 -> -21095.015
A22: 45626 | G22: 219000 | H22: =H27+F22-G22 -> -43095.015 | I22: 240 | J22: 60 | K22: =I22*J22/100 -> 144
C23: adet | D23: asg ücret | E23: yıllık
B24: aylık 2 asgari ücret | C24: 24 | D24: 22104 | E24: =D24*C24 -> 530496
D25: aylık KİRA | E25: =E24/12 -> 44208
B27: keşif harç masraf için emrullaha havale | F27: 7080 | H27: =H28+F27-G27 -> 175904.98 | K27: =K22+I22 -> 384
A28: 45626 | B28: tüfe 11 | C28: 2657.23 | D28: =(C28/C30)-1 -> 0.022440177 | E28: =C28 -> 2657.23 | F28: =H29*D28 -> 3705.3146 | H28: =H29+F28-G28 -> 168824.98 | K28: =K27/12 -> 32
B29: 2024 - 12/12 Kasım | E29: =E31+E30 -> 28469.069 | F29: =E29 -> 28469.069 | H29: =H30+F29-G29 -> 165119.67
A30: 45595 | B30: tüfe 10 | C30: 2598.91 | D30: =(C30/C32)-1 -> 0.028798651 | E30: =F31*D30 -> 796.92054 | F30: =H31*D30 -> 3825.1926 | H30: =H31+F30-G30 -> 136650.6
B31: 2023-2024 - 11/12 Ekim | E31: =E33+E32 -> 27672.148 | F31: =E31 -> 27672.148 | H31: =H32+F31-G31 -> 132825.41
A32: 45565 | B32: tüfe 9 | C32: 2526.16 | D32: =(C32/C34)-1 -> 0.029681985 | E32: =F33*D32 -> 797.68734 | F32: =IF(H33<=0,,(H33*D32)) -> 3031.1858 | H32: =H33+F32-G32 -> 105153.26
B33: 2023 - 2024 10/12 Eylül | E33: =E35+E34 -> 26874.461 | F33: =E33 -> 26874.461 | H33: =H34+F33-G33 -> 102122.07
A34: 45534 | B34: tüfe 8 | C34: 2453.34 | D34: =(C34/C36)-1 -> 0.024744163 | E34: =F35*D34 -> 648.92884 | F34: =IF(H35<=0,,(H35*D34)) -> 1816.9796 | H34: =H35+F34-G34 -> 75247.613
B35: 2023-2024 - 9/12 Ağustos | E35: =E37+E36 -> 26225.532 | F35: =E35 -> 26225.532 | H35: =H36+F35-G35 -> 73430.634
A36: 45503 | B36: tüfe 7 | C36: 2394.1 | D36: =(C36/C38)-1 -> 0.032255561 | E36: =F37*D36 -> 819.48626 | F36: =IF(H37<=0,,(H37*D36)) -> 1475.0485 | H36: =H37+F36-G36 -> 47205.102
B37: 2023-2024 - 8/12 Temmuz | E37: =E39+E38 -> 25406.046 | F37: =E37 -> 25406.046 | H37: =H38+F37-G37 -> 45730.053
A38: 45473 | B38: tüfe 6 | C38: 2319.29 | D38: =(C38/C40)-1 -> 0.016407739 | E38: =F39*D38 -> 410.12653 | F38: =IF(H39<=0,,(H39*D38)) -> 328.08783 | H38: =H39+F38-G38 -> 20324.007
B39: 2023-2024 - 7/12 Haziran | E39: =E41+E40 -> 24995.919 | F39: =E39 -> 24995.919 | H39: =H40+F39-G39 -> 19995.919
A40: 45442 | B40: tüfe 5 | C40: 2281.85 | D40: =(C40/C42)-1 -> 0.033680634 | E40: =F41*D40 -> 673.61268 | F40: =IF(H41<=0,,(H41*D40)) -> 0 | H40: =H41+F40-G40 -> -5000
B41: 2023-2024 - 6/12 Mayıs | E41: =E43+E42 -> 24322.307 | F41: =F43 -> 20000 | H41: =H42+F41-G41 -> -5000
A42: 45412 | B42: tüfe 4 | C42: 2207.5 | D42: =(C42/C44)-1 -> 0.031797595 | E42: =F43*D42 -> 635.95189 | F42: =IF(H43<=0,,(H43*D42)) -> 0 | H42: =H43+F42-G42 -> -25000
...

Sheet SnyE503-25
B1: SnyE.30.20240606.091 - SULEYMAN AKAN | G1: 100 m2 ESTE
A3: Tarih | B3: Açıklama | E3: Kira bedeli | F3: Ödeme | G3: Bakiye
B4: Toplamlar | E4: =SUM(E9:E20) -> 132624 | F4: =SUM(F9:F20) -> 0 | G4: =G20 -> 132624
B5: Masraf | E5: =G40 -> 0
B6: Teminat | E6: =G37 -> -800
F7: NET | G7: =F4-E5 -> 0
B8: ,
A9: 45806 | B9: 06-06-2025-31-12-2025 Bedeli | C9: 6 | D9: 22104 | E9: =D9*C9 -> 132624 | G9: =E9-F9 -> 132624
G10: =E10-F10+G9 -> 132624
G11: =E11-F11+G10 -> 132624
B12: 45739 | G12: =E12-F12+G11 -> 132624
G13: =E13-F13+G12 -> 132624
G14: =E14-F14+G13 -> 132624
G15: =E15-F15+G14 -> 132624
G16: =E16-F16+G15 -> 132624
G17: =E17-F17+G16 -> 132624
G18: =E18-F18+G17 -> 132624
G19: =E19-F19+G18 -> 132624
G20: =E20-F20+G19 -> 132624
A23: - 2023 - | B23: ELEKTRİK | C23: Su | E23: Tutarı | G23: ( 1000 TL )
B24: Devreden Teminat | G24: -800
B25: Su-Elektrik Ocak | C25: 0 | G25: =E25-F25+G24 -> -800
B26: Su-Elektrik Şubat | C26: 0 | G26: =E26-F26+G25 -> -800
B27: Su-Elektrik art | G27: =E27-F27+G26 -> -800
B28: Su-Elektrik Nisan | G28: =E28-F28+G27 -> -800
B29: Su-Elektrik Mayıs | G29: =E29-F29+G28 -> -800
B30: Su-Elektrik Haziran | G30: =E30-F30+G29 -> -800
B31: Su-Elektrik Temmuz | G31: =E31-F31+G30 -> -800
B32: Su-Elektrik Ağustos | G32: =E32-F32+G31 -> -800
B33: Su-Elektrik Eylül | G33: =E33-F33+G32 -> -800
B34: Su-Elektrik Ekim | G34: =E34-F34+G33 -> -800
B35: Su-Elektrik Kasım | G35: =E35-F35+G34 -> -800
B36: Su-Elektrik Aralık | G36: =E36-F36+G35 -> -800
A37: 45291 | B37: Devreden Teminat | C37: =SUM(C25:C36) -> 0 | G37: =E37-F37+G36 -> -800
A40: snyE | B40: Açıklamalar-Masraflar | G40: =SUM(F41:F63) -> 0
B42: 2025-26
C44: 12 | D44: 22102 | E44: =D44*C44 -> 265224
B55: 2024-25
B56: Motorcu
A57: 45402 | B57: Süleyman AKAN
...

Sheet SnyE502-22
B1: 085-20230830-SNYE-02-SZL CIHAN CAM | F1: 100 m2 ESTE
A3: Tarih | B3: Açıklama | D3: Kira bedeli | E3: Ödeme | F3: Bakiye
B4: Toplamlar | D4: =SUM(D9:D20) -> 7000 | E4: =SUM(E9:E20) -> 0 | F4: =F20 -> 7000
B5: Masraf | D5: =F40 -> 0
B6: Teminat | D6: =F37 -> -794.6
E7: NET | F7: =E4-D5 -> 0
B8: ,
A9: 45167 | F9: =D9-E9 -> 0
F10: =D10-E10+F9 -> 0
F11: =D11-E11+F10 -> 0
F12: =D12-E12+F11 -> 0
F13: =D13-E13+F12 -> 0
F14: =D14-E14+F13 -> 0
A15: 44956 | B15: Kira Bedeli senet 5/5 7000 senet | C15: 45322 | D15: 7000 | F15: =D15-E15+F14 -> 7000
F16: =D16-E16+F15 -> 7000
F17: =D17-E17+F16 -> 7000
F18: =D18-E18+F17 -> 7000
F19: =D19-E19+F18 -> 7000
F20: =D20-E20+F19 -> 7000
A23: - 2023 - | B23: ELEKTRİK | C23: Su | D23: Tutarı | F23: ( 1000 TL )
B24: Devreden Teminat | F24: -800
B25: Su-Elektrik Ocak | C25: 0 | D25: 381.33 | E25: 431.36 | F25: =D25-E25+F24 -> -850.03
B26: Su-Elektrik Şubat | C26: 0 | D26: 237.14 | E26: 237.11 | F26: =D26-E26+F25 -> -850
B27: Su-Elektrik art | D27: 55.4 | F27: =D27-E27+F26 -> -794.6
B28: Su-Elektrik Nisan | F28: =D28-E28+F27 -> -794.6
B29: Su-Elektrik Mayıs | F29: =D29-E29+F28 -> -794.6
B30: Su-Elektrik Haziran | F30: =D30-E30+F29 -> -794.6
B31: Su-Elektrik Temmuz | F31: =D31-E31+F30 -> -794.6
B32: Su-Elektrik Ağustos | F32: =D32-E32+F31 -> -794.6
B33: Su-Elektrik Eylül | F33: =D33-E33+F32 -> -794.6
B34: Su-Elektrik Ekim | F34: =D34-E34+F33 -> -794.6
B35: Su-Elektrik Kasım | F35: =D35-E35+F34 -> -794.6
B36: Su-Elektrik Aralık | F36: =D36-E36+F35 -> -794.6
A37: 45291 | B37: Devreden Teminat | C37: =SUM(C25:C36) -> 0 | F37: =D37-E37+F36 -> -794.6
A40: snyE | B40: Açıklamalar-Masraflar | F40: =SUM(E41:E54) -> 0
B42: Motorcu
A43: 44774 | B43: Cihan Çam
B44: 22-23 kira bedeli ödendi | D44: 45000
A45: 44774 | B45: Anlaşma yapıldı
A47: 44803 | B47: Kira Başlangıç Tarihi
...

Sheet SnyF601-22
B1: 082-SnF-02-230101-merdalKipel | G1: 100 m2 ESTE
A3: Tarih | B3: Açıklama | D3: Bedel | E3: Tutar | F3: Ödeme | G3: Bakiye
B4: Toplamlar | E4: =SUM(E9:E39) -> 447218.54 | F4: =SUM(F9:F39) -> 184917.52 | G4: =#ref! -> #NAME?
B5: Masraf | E5: =G59 -> 0
B6: Teminat | E6: =G56 -> -2824.53
A7: - 2024 - | F7: NET | G7: =F4-E5 -> 184917.52
B8: ,
A9: 44957 | B9: Ocak | C9: 6.65 | E9: 6920 | F9: 6920 | G9: =E9-F9 -> 0
B10: Şubat | C10: 3.15 | E10: =E9+(E9*C9/100) -> 7380.18 | G10: =E10-F10+G9 -> 7380.18
B11: Mart | C11: 2.29 | E11: =E10+(E10*C10/100) -> 7612.6557 | G11: =E11-F11+G10 -> 14992.836
B12: Nisan avukattan 13000 den | C12: 2.39 | E12: =E11+(E11*C11/100) -> 7786.9855 | F12: 8425.46 | G12: =E12-F12+G11 -> 14354.361
B13: Mayıs 0,04 | C13: 0.04 | E13: =E12+(E12*C12/100) -> 7973.0944 | F13: 28080 | G13: =E13-F13+G12 -> -5752.5444
B14: Haziran | C14: 3.92 | E14: =E13+(E13*C13/100) -> 7976.2837 | G14: =E14-F14+G13 -> 2223.7393
B15: Temmuz | C15: 9.49 | E15: =E14+(E14*C14/100) -> 8288.954 | F15: 50000 | G15: =E15-F15+G14 -> -39487.307
B16: Ağustos | C16: 9.09 | E16: =E15+(E15*C15/100) -> 9075.5757 | G16: =E16-F16+G15 -> -30411.731
B17: Eylül 4,75 | C17: 4.75 | E17: =E16+(E16*C16/100) -> 9900.5456 | G17: =E17-F17+G16 -> -20511.185
B18: Ekim | C18: 3.43 | E18: =E17+(E17*C17/100) -> 10370.821 | G18: =E18-F18+G17 -> -10140.364
A19: 45260 | B19: Kasım - Aralık dahil hesap sıfırlandı | C19: 42.6451 | E19: =E18+(E18*C18/100) -> 10726.541 | F19: 15887.06 | G19: =E19-F19+G18 -> -15300.883
A20: 45291 | B20: Aralık | C20: 2.93 | E20: =E19+(E19*C19/100) -> 15300.885 | G20: =E20-F20+G19 -> 0.0013347145
A22: 45322 | B22: Ocak | C22: 6.71 | E22: 17002 | G22: =E22-F22+G20 -> 17002.001
B23: Şubat | C23: 4.53 | E23: =E22+(E22*C22/100) -> 18142.834 | G23: =E23-F23+G22 -> 35144.836
B24: Mart | C24: 3.16 | E24: =E23+(E23*C23/100) -> 18964.705 | G24: =E24-F24+G23 -> 54109.54
B25: Kira vergi farkı | F25: -3795 | G25: =E25-F25+G24 -> 57904.54
A26: 45397 | B26: Nisan | C26: 3.18 | E26: =E24+(E24*C24/100) -> 19563.989 | F26: 85000 | G26: =E26-F26+G25 -> -7531.4706
B27: icra masrafı | F27: -5600 | G27: =E27-F27+G26 -> -1931.4706
B28: Mayıs | C28: 3.37 | E28: =E26+(E26*C26/100) -> 20186.124 | G28: =E28-F28+G27 -> 18254.653
B29: Haziran | C29: 3.6 | E29: =E28+(E28*C28/100) -> 20866.396 | G29: =E29-F29+G28 -> 39121.05
B30: Temmuz | C30: 3.6 | E30: =E29+(E29*C29/100) -> 21617.587 | G30: =E30-F30+G29 -> 60738.637
B31: Ağustos | E31: =E30+(E30*C30/100) -> 22395.82 | G31: =E31-F31+G30 -> 83134.457
B32: Eylül | E32: =E31+(E31*C31/100) -> 22395.82 | G32: =E32-F32+G31 -> 105530.28
B33: Ekim | E33: =E32+(E32*C32/100) -> 22395.82 | G33: =E33-F33+G32 -> 127926.1
B34: Kasım | E34: =E33+(E33*C33/100) -> 22395.82 | G34: =E34-F34+G33 -> 150321.92
B35: Aralık | E35: =E34+(E34*C34/100) -> 22395.82 | G35: =E35-F35+G34 -> 172717.74
B36: Ocak | E36: =E35+(E35*C35/100) -> 22395.82 | G36: =E36-F36+G35 -> 195113.56
B37: Şubat | E37: =E36+(E36*C36/100) -> 22395.82 | G37: =E37-F37+G36 -> 217509.38
B38: Mart | E38: =E37+(E37*C37/100) -> 22395.82 | G38: =E38-F38+G37 -> 239905.2
B39: Nisan | E39: =E38+(E38*C38/100) -> 22395.82 | G39: =E39-F39+G38 -> 262301.02
A42: =A7 -> - 2024 - | B42: ELEKTRİK | C42: Su | E42: Tutarı | G42: ( 3100 TL )
B43: Devreden Teminat | G43: -2510.63
B44: Su-Elektrik Ocak | C44: 0 | E44: 781.86 | F44: 891.32 | G44: =E44-F44+G43 -> -2620.09
...

Sheet snyF-HSP
C4: 31-3-2022 Asgari ücret 4253 TL - 48000TL = 12 asgari ücret
C6: 31-3-2022 - 31-12-2022 9 aylık tutar | E6: 48000 | H6: =I4+E6-G6 -> 48000
B7: 44651 | C7: Nakit Ödeme | G7: 28000 | H7: =H6+E7-G7 -> 20000
B8: 44681 | C8: 10-05-2022 - 4000 nakit ödeme | G8: 4000 | H8: =H7+E8-G8 -> 16000
B9: 44711 | C9: 20-06-2022 - 4000 nakit ödeme | G9: 4000 | H9: =H8+E9-G9 -> 12000
B10: 44742 | C10: Ödeme yapılmadı 4000 Ocak 2023 ödenmedi | H10: =H9+E10-G10 -> 12000
B11: 44772 | C11: Ödeme yapılmadı 4000 Şubat 2023 ödenmedi | H11: =H10+E11-G11 -> 12000
B12: 44803 | C12: Ödeme yapılmadı 4000 Mart 2023 ödenmedi | H12: =H11+E12-G12 -> 12000
B14: Son 3 ayın ödemesi yapılmadığı için (3x4000) ilk kira dönemi Nisan Aralık olarak kapatıldı
B15: Ocak 2023 ile yeni fiyat (6920) ve yeni dönem uygulandı | E15: aylık kira
D16: tüfe | E16: bedeli | F16: ödenecek | G16: ödeme | H16: bakiye
B17: 44957 | C17: Ocak | D17: 6.65 | E17: 6920 | G17: 6920 | H17: =E17-G17 -> 0
C18: Şubat | D18: 3.15 | E18: =E17+(E17*D17/100) -> 7380.18 | F18: =E18 -> 7380.18 | H18: =F18-G18+H17 -> 7380.18
C19: Mart | D19: 2.29 | E19: =E18+(E18*D18/100) -> 7612.6557 | F19: =E19 -> 7612.6557 | H19: =F19-G19+H18 -> 14992.836
C20: Nisan avukattan 13000 den | D20: 2.39 | E20: =E19+(E19*D19/100) -> 7786.9855 | F20: =E20 -> 7786.9855 | G20: 8425.46 | H20: =F20-G20+H19 -> 14354.361
C21: Mayıs 0,04 | D21: 0.04 | E21: =E20+(E20*D20/100) -> 7973.0944 | F21: =E21 -> 7973.0944 | G21: 28080 | H21: =F21-G21+H20 -> -5752.5444
C22: Haziran | D22: 3.92 | E22: =E21+(E21*D21/100) -> 7976.2837 | F22: =E22 -> 7976.2837 | H22: =F22-G22+H21 -> 2223.7393
C23: Temmuz | D23: 9.49 | E23: =E22+(E22*D22/100) -> 8288.954 | F23: =E23 -> 8288.954 | G23: 50000 | H23: =F23-G23+H22 -> -39487.307
C24: Ağustos | D24: 9.09 | E24: =E23+(E23*D23/100) -> 9075.5757 | F24: =E23 -> 8288.954 | H24: =F24-G24+H23 -> -31198.353
C25: Eylül 4,75 | D25: 4.75 | E25: =E24+(E24*D24/100) -> 9900.5456 | F25: =E23 -> 8288.954 | H25: =F25-G25+H24 -> -22909.399
C26: Ekim | D26: 3.43 | E26: =E25+(E25*D25/100) -> 10370.821 | F26: =E23 -> 8288.954 | H26: =F26-G26+H25 -> -14620.445
C27: Kasım | D27: 3.28 | E27: =E26+(E26*D26/100) -> 10726.541 | F27: =E23 -> 8288.954 | G27: 15887.06 | H27: =F27-G27+H26 -> -22218.551
B28: 45291 | C28: Aralık | D28: 2.93 | E28: =E27+(E27*D27/100) -> 11078.371 | F28: =E23 -> 8288.954 | H28: =F28-G28+H27 -> -13929.597
B29: 45322 | C29: Ocak yıllık 83160*57,5%=131->168 | D29: 6.71 | E29: 14000 | F29: =E23 -> 8288.954 | H29: =F29-G29+H28 -> -5640.6428
C30: Şubat | D30: 4.53 | E30: =E29+(E29*D29/100) -> 14939.4 | F30: =E30 -> 14939.4 | H30: =F30-G30+H29 -> 9298.7572
C31: Mart | D31: 3.16 | E31: =E30+(E30*D30/100) -> 15616.155 | F31: =E31 -> 15616.155 | H31: =F31-G31+H30 -> 24914.912
C32: Kira vergi farkı | E32: 3795 | F32: =E32 -> 3795 | H32: =F32-G32+H31 -> 28709.912
C33: icra masrafı | E33: 5600 | F33: =E33 -> 5600 | H33: =F33-G33+H32 -> 34309.912
C34: Sözleşme DV | E34: 278.97 | F34: =E34 -> 278.97 | H34: =F34-G34+H33 -> 34588.882
C35: Usulsüzlük cezası | E35: 10000 | F35: =E35 -> 10000 | H35: =F35-G35+H34 -> 44588.882
C36: Nisan | D36: 3.18 | E36: =E31+(E31*D31/100) -> 16109.625 | F36: =E36 -> 16109.625 | G36: 85000 | H36: =F36-G36+H35 -> -24301.493
C37: Mayıs | D37: 3.37 | E37: =E36+(E36*D36/100) -> 16621.911 | F37: =E36 -> 16109.625 | H37: =F37-G37+H36 -> -8191.8673
C38: Haziran | D38: 1.64 | E38: =E37+(E37*D37/100) -> 17182.07 | F38: =E37 -> 16621.911 | H38: =F38-G38+H37 -> 8430.0441
C39: Temmuz | D39: 3.23 | E39: =E38+(E38*D38/100) -> 17463.856 | F39: =E39 -> 17463.856 | H39: =F39-G39+H38 -> 25893.9
C40: Ağustos | D40: 2.47 | E40: =E39+(E39*D39/100) -> 18027.938 | F40: =E40 -> 18027.938 | H40: =F40-G40+H39 -> 43921.838
C41: Eylül | D41: 2.97 | E41: =E40+(E40*D40/100) -> 18473.228 | F41: =E41 -> 18473.228 | H41: =F41-G41+H40 -> 62395.067
C42: Ekim | D42: 2.88 | E42: =E41+(E41*D41/100) -> 19021.883 | F42: =E42 -> 19021.883 | H42: =F42-G42+H41 -> 81416.95
C43: Kasım | D43: 2.24 | E43: =E42+(E42*D42/100) -> 19569.713 | F43: =E43 -> 19569.713 | H43: =F43-G43+H42 -> 100986.66
C44: boya masrafı | F44: 8000 | H44: =F44-G44+H43 -> 108986.66
C45: ÖDEME | G45: 148500 | H45: =F45-G45+H44 -> -39513.337
...

Sheet snyF-HSP (2025)
C3: 45739
D5: tüfe | E5: b.fiyat | F5: ödenecek | G5: ödeme | H5: bakiye
H6: =I4+E6-G6 -> 0
B7: 44651 | F7: 48000 | G7: 28000 | H7: =F7-G7+H6 -> 20000
B8: 44681 | C8: 10-05-2022 | G8: 4000 | H8: =F8-G8+H7 -> 16000
B9: 44711 | C9: 20-06-2022 | G9: 4000 | H9: =F9-G9+H8 -> 12000
B10: 44742 | H10: =F10-G10+H9 -> 12000
B11: 44772 | H11: =F11-G11+H10 -> 12000
B12: 44803 | C12: 2022 YILINDA ÖDENMEYEN KİRALAR İÇİN | H12: =F12-G12+H11 -> 12000
B13: 44834 | C13: TÜFE FARKI HESAPLANMADI - EKLENMEDİ | H13: =F13-G13+H12 -> 12000
B14: 44864 | H14: =F14-G14+H13 -> 12000
B15: 44895 | C15: ÖDEME YAPILMADIĞI İÇİN SON 3 AY DÜŞÜLDÜ | F15: -12000 | H15: =F15-G15+H14 -> 0
C16: HESAP SIFIRLANDI VE 2023 YILI TÜFE FARKLI FİYAT ANLAŞILDI
B17: 44925 | C17: 2022 SONRASI TÜFE FARKI AYLIK OLARAK HESABA EKLENDİ | H17: =F17-G17+H15 -> 0
B18: 44956 | C18: BANKA ÖDEMESİ | D18: 6.65 | E18: 6920 | F18: =E18 -> 6920 | G18: 6920 | H18: =F18-G18+H17 -> 0
B19: 44985 | D19: 3.15 | E19: =E18+(E18*D18/100) -> 7380.18 | F19: =E19 -> 7380.18 | H19: =F19-G19+H18 -> 7380.18
B20: 45015 | D20: 2.29 | E20: =E19+(E19*D19/100) -> 7612.6557 | F20: =E20 -> 7612.6557 | H20: =F20-G20+H19 -> 14992.836
C21: ÖDEME YAPILMADIĞI İÇİN İCRAYA GİDİLDİ
B22: 45046 | C22: icradan | D22: 2.39 | E22: =E20+(E20*D20/100) -> 7786.9855 | F22: =E22 -> 7786.9855 | G22: 8425.46 | H22: =F22-G22+H20 -> 14354.361
B23: 45076 | C23: BANKA ÖDEMESİ | D23: 0.04 | E23: =E22+(E22*D22/100) -> 7973.0944 | F23: =E23 -> 7973.0944 | G23: 28080 | H23: =F23-G23+H22 -> -5752.5444
B24: 45107 | D24: 3.92 | E24: =E23+(E23*D23/100) -> 7976.2837 | F24: =E24 -> 7976.2837 | H24: =F24-G24+H23 -> 2223.7393
B25: 45137 | D25: 9.49 | E25: =E24+(E24*D24/100) -> 8288.954 | F25: =E25 -> 8288.954 | G25: 50000 | H25: =F25-G25+H24 -> -39487.307
B26: 45168 | D26: 9.09 | E26: =E25+(E25*D25/100) -> 9075.5757 | F26: =E25 -> 8288.954 | H26: =F26-G26+H25 -> -31198.353
B27: 45199 | D27: 4.75 | E27: =E26+(E26*D26/100) -> 9900.5456 | F27: =E25 -> 8288.954 | H27: =F27-G27+H26 -> -22909.399
B28: 45229 | D28: 3.43 | E28: =E27+(E27*D27/100) -> 10370.821 | F28: =E25 -> 8288.954 | H28: =F28-G28+H27 -> -14620.445
B29: 45260 | D29: 3.28 | E29: =E28+(E28*D28/100) -> 10726.541 | F29: =E25 -> 8288.954 | G29: 15887.06 | H29: =F29-G29+H28 -> -22218.551
B30: 45290 | D30: 2.93 | E30: =E29+(E29*D29/100) -> 11078.371 | F30: =E25 -> 8288.954 | H30: =F30-G30+H29 -> -13929.597
B31: 45321 | D31: 6.71 | E31: =E30+(E30*D30/100) -> 11402.967 | F31: =E25 -> 8288.954 | H31: =F31-G31+H30 -> -5640.6428
B32: 45350 | D32: 4.53 | E32: =E31+(E31*D31/100) -> 12168.107 | F32: =E32 -> 12168.107 | H32: =F32-G32+H31 -> 6527.4638
B33: 45381 | D33: 3.16 | E33: =E32+(E32*D32/100) -> 12719.322 | F33: =E33 -> 12719.322 | H33: =F33-G33+H32 -> 19246.786
C34: Kira vergi farkı | E34: 3795 | F34: =E34 -> 3795 | H34: =F34-G34+H33 -> 23041.786
C35: icra masrafı | E35: 5600 | F35: =E35 -> 5600 | H35: =F35-G35+H34 -> 28641.786
C36: Sözleşme DV | E36: 278.97 | F36: =E36 -> 278.97 | H36: =F36-G36+H35 -> 28920.756
C37: Usulsüzlük cezası | E37: 10000 | F37: =E37 -> 10000 | H37: =F37-G37+H36 -> 38920.756
B38: 45762 | C38: BANKA ÖDEMESİ | D38: 3.18 | E38: =E33+(E33*D33/100) -> 13121.252 | F38: =E38 -> 13121.252 | G38: 85000 | H38: =F38-G38+H37 -> -32957.992
B39: 45442 | D39: 3.37 | E39: =E38+(E38*D38/100) -> 13538.508 | F39: =E38 -> 13121.252 | H39: =F39-G39+H38 -> -19836.74
B40: 45473 | D40: 1.64 | E40: =E39+(E39*D39/100) -> 13994.756 | F40: =E40 -> 13994.756 | H40: =F40-G40+H39 -> -5841.9837
B41: 45503 | D41: 3.23 | E41: =E40+(E40*D40/100) -> 14224.27 | F41: =E41 -> 14224.27 | H41: =F41-G41+H40 -> 8382.2862
B42: 45534 | D42: 2.47 | E42: =E41+(E41*D41/100) -> 14683.714 | F42: =E42 -> 14683.714 | H42: =F42-G42+H41 -> 23066
B43: 45565 | D43: 2.97 | E43: =E42+(E42*D42/100) -> 15046.402 | F43: =E43 -> 15046.402 | H43: =F43-G43+H42 -> 38112.402
...

Sheet SnyG702-22
B1: SnyG | G1: 100 m2 Sanayi Pano
A3: Tarih | B3: Açıklama | E3: Kira bedeli | F3: Ödeme | G3: Bakiye
B4: Toplamlar | E4: =SUM(E9:E20) -> 110513 | F4: =SUM(F9:F20) -> 0 | G4: =G20 -> 110513
B5: Masraf | E5: =G85 -> 0
B6: Teminat | E6: =G82 -> -1200
F7: NET | G7: =F4-E5 -> 0
B8: ,
A9: 45564 | B9: 30-09-2024 – 29-09-2025 | G9: =E9-F9 -> 0
B10: 12*17002 | C10: 12 | D10: 17002 | G10: =E10-F10+G9 -> 0
G11: =E11-F11+G10 -> 0
B12: ödeme yapılmadI | G12: =E12-F12+G11 -> 0
B13: 15-01-2025 TE BOŞALTTI | G13: =E13-F13+G12 -> 0
C14: AY | G14: =E14-F14+G13 -> 0
B15: OTURDUĞU SÜRE 2024-2025 | C15: 3.5 | D15: 17002 | E15: =D15*C15 -> 59507 | G15: =E15-F15+G14 -> 59507
B16: ZAMANINDA BİLDİRİM YAPMADIĞI İÇİN | C16: 3 | D16: 17002 | E16: =D16*C16 -> 51006 | G16: =E16-F16+G15 -> 110513
G17: =E17-F17+G16 -> 110513
B18: 45739 | G18: =E18-F18+G17 -> 110513
G19: =E19-F19+G18 -> 110513
G20: =E20-F20+G19 -> 110513
B22: 2023 kirası | E22: 96000 | G22: 0
B23: eylül 2024 tüfe | C23: 63.47 | E23: =E22*C23/100 -> 60931.2 | G23: 0
B24: 30-09-2024 – 29-09-2025 kira bedeli | E24: =SUM(E22:E23) -> 156931.2 | G24: 0
B25: 12 ay | C25: 12 | E25: =E24/C25 -> 13077.6 | G25: 0
B26: oturulan ay | C26: 3.5 | E26: =E25*C26 -> 45771.6 | G26: =E26-F26+G25 -> 45771.6
G27: =E27-F27+G26 -> 45771.6
B28: 46079 | G28: =E28-F28+G27 -> 45771.6
A40: - 2023 - | B40: ELEKTRİK | D40: Su | E40: Tutarı
B41: Devreden Teminat
B42: Su-Elektrik Ocak | D42: 40 | E42: 483.72 | F42: 483.72
B43: Su-Elektrik Şubat | E43: 439.85 | F43: 439.85
B44: Su-Elektrik art
B45: Su-Elektrik Nisan
B46: Su-Elektrik Mayıs
B47: Su-Elektrik Haziran
B48: Su-Elektrik Temmuz
B49: Su-Elektrik Ağustos
B50: Su-Elektrik Eylül
B51: Su-Elektrik Ekim
B52: Su-Elektrik Kasım
B53: Su-Elektrik Aralık
...

Sheet SnH_yazıhane
A2: 2023 | B2: SnyH Yazıhane | D2: 300 m2 | F2: =SUM(F6:F55) -> 3999.1 | G2: =F2 -> 3999.1
A4: Tarih | B4: Açıklama | C4: Kira bedeli | D4: Ödeme | E4: Bakiye | F4: Masraf | G4: Bakiye
A6: 45321 | B6: Elektrik 1 | F6: 169.14 | G6: =G5+E6-F6 -> -169.14
A7: 45350 | B7: Elektrik 2- | F7: 67.09 | G7: =G6+E7-F7 -> -236.23
A8: 45381 | B8: Elektrik 3- | F8: 225.66 | G8: =G7+E8-F8 -> -461.89
A9: 45412 | B9: Elektrik 4- | F9: 286.72 | G9: =G8+E9-F9 -> -748.61
A10: 45442 | B10: Elektrik 5- | F10: 100 | G10: =G9+E10-F10 -> -848.61
A11: 45426 | B11: Bina Vergisi 1 | F11: 1415 | G11: =G10+E11-F11 -> -2263.61
A12: 45426 | B12: Kültür Vergisi 1 | F12: 141.5 | G12: =G11+E12-F12 -> -2405.11
A13: 45473 | B13: Elektrik 6– | F13: 37.49 | G13: =G12+E13-F13 -> -2442.6
A14: 45503 | B14: Elektrik 7– | G14: =G13+E14-F14 -> -2442.6
A15: 45534 | B15: Elektrik 8- | G15: =G14+E15-F15 -> -2442.6
A16: 45565 | B16: Elektrik 9- | G16: =G15+E16-F16 -> -2442.6
A17: 45595 | B17: Elektrik 10- | G17: =G16+E17-F17 -> -2442.6
A18: 45579 | B18: Bina Vergisi 2 | F18: 1415 | G18: =G17+E18-F18 -> -3857.6
A19: 45579 | B19: Kültür Vergisi 2 | F19: 141.5 | G19: =G18+E19-F19 -> -3999.1
A20: 45626 | B20: Elektrik 11- | G20: =G19+E20-F20 -> -3999.1
A21: 45656 | B21: Elektrik 12- | G21: =G20+E21-F21 -> -3999.1
B22: su | F22: 0 | G22: =G21+E22-F22 -> -3999.1

Sheet NAZAN_25
B2: 2025 YILI NAZAN BALCI
C3: Yapılacak | D3: Kalacak | E3: Yapılan | H3: Kalan
C4: Ödeme | D4: Bakiye | E4: Ödeme | H4: Bakiye
D5: 138749.76 | G5: 2024 yıl sonu nazan devreden kira geliri | H5: =D5 -> 138749.76 | I5: İŞ 801
D7: + | G7: 2025 yılı Toplam | H7: =H31*-1 -> 139111.94
H8: =H7+H5 -> 277861.7
A9: 45661 | D9: =H8-C9 -> 277861.7 | H9: =H8-E9 -> 277861.7
A10: 45689 | D10: =D9-C10 -> 277861.7 | H10: =H9-E10 -> 277861.7
A11: 45717 | D11: =D10-C11 -> 277861.7 | H11: =H10-E11 -> 277861.7
A12: 45755 | B12: havale | D12: =D11-C12 -> 277861.7 | E12: 20000 | H12: =H11-E12 -> 257861.7
A13: 45786 | B13: havale | D13: =D12-C13 -> 277861.7 | E13: 20000 | H13: =H12-E13 -> 237861.7
A14: 45818 | B14: havale | D14: =D13-C14 -> 277861.7 | E14: 20000 | H14: =H13-E14 -> 217861.7
A15: 45846 | B15: havale | D15: =D14-C15 -> 277861.7 | E15: 20000 | H15: =H14-E15 -> 197861.7
A16: 45855 | B16: havale | D16: =D15-C16 -> 277861.7 | E16: 30000 | H16: =H15-E16 -> 167861.7
A17: 45901 | B17: havale | D17: =D16-C17 -> 277861.7 | E17: 20000 | H17: =H16-E17 -> 147861.7
A18: 45944 | B18: havale | D18: =D17-C18 -> 277861.7 | E18: 20000 | H18: =H17-E18 -> 127861.7
A19: 45966 | B19: havale | D19: =D18-C19 -> 277861.7 | E19: 20000 | H19: =H18-E19 -> 107861.7
A20: 45992 | B20: havale | D20: =D19-C20 -> 277861.7 | E20: 20000 | H20: =H19-E20 -> 87861.704
A21: 46034 | B21: havale | E21: 25000 | H21: =H20-E21 -> 62861.704
A22: 46058 | B22: havale | E22: 25000 | H22: =H21-E22 -> 37861.704
B29: Hisse Oranı | D29: 0.764616 | E29: =1-D29 -> 0.235384
A30: Tarih | B30: Açıklama | C30: snyA-H | D30: Oran % | E30: Oran TL Tutar | F30: Ödendi | G30: Oran TL | H30: Genel Toplam | I30: Sütun1 | J30: Sütun2
B31: Toplam Gelir | C31: =SUBTOTAL(109,C32:C46) -> 591000 | D31: =SUBTOTAL(109,D32:D46) -> 591000 | E31: =SUM(E32:E46) -> 0 | G31: =SUBTOTAL(109,$G$32:$G$46) -> -139111.94 | H31: =H32 -> -139111.94
A32: 46021 | B32: snyH- Yazıhane | D32: =IF(F32=1,$C32,0) -> 0 | E32: =IF(F32=0,C32*$E$29*-1,0) -> 0 | F32: 0 | G32: =IF(F32=1,C32*$E$29*-1,0) -> 0 | H32: =H33+G32 -> -139111.94
A33: 45992 | B33: sny CD Ali demirel | C33: 301000 | D33: =IF(F33=1,$C33,0) -> 301000 | E33: =IF(F33=0,C33*$E$29*-1,0) -> 0 | F33: 1 | G33: =IF(F33=1,C33*$E$29*-1,0) -> -70850.584 | H33: =H34+G33 -> -139111.94
D34: =IF(F34=1,$C34,0) -> 0 | E34: =IF(F34=0,C34*$E$29*-1,0) -> 0 | F34: 0 | G34: =IF(F34=1,C34*$E$29*-1,0) -> 0 | H34: =H35+G34 -> -68261.36
D35: =IF(F35=1,$C35,0) -> 0 | E35: =IF(F35=0,C35*$E$29*-1,0) -> 0 | F35: 0 | G35: =IF(F35=1,C35*$E$29*-1,0) -> 0 | H35: =H36+G35 -> -68261.36
D36: =IF(F36=1,$C36,0) -> 0 | E36: =IF(F36=0,C36*$E$29*-1,0) -> 0 | F36: 0 | G36: =IF(F36=1,C36*$E$29*-1,0) -> 0 | H36: =H37+G36 -> -68261.36
D37: =IF(F37=1,$C37,0) -> 0 | E37: =IF(F37=0,C37*$E$29*-1,0) -> 0 | F37: 0 | G37: =IF(F37=1,C37*$E$29*-1,0) -> 0 | H37: =H38+G37 -> -68261.36
D38: =IF(F38=1,$C38,0) -> 0 | E38: =IF(F38=0,C38*$E$29*-1,0) -> 0 | F38: 0 | G38: =IF(F38=1,C38*$E$29*-1,0) -> 0 | H38: =H39+G38 -> -68261.36
D39: =IF(F39=1,$C39,0) -> 0 | E39: =IF(F39=0,C39*$E$29*-1,0) -> 0 | F39: 0 | G39: =IF(F39=1,C39*$E$29*-1,0) -> 0 | H39: =H40+G39 -> -68261.36
D40: =IF(F40=1,$C40,0) -> 0 | E40: =IF(F40=0,C40*$E$29*-1,0) -> 0 | F40: 0 | G40: =IF(F40=1,C40*$E$29*-1,0) -> 0 | H40: =H41+G40 -> -68261.36
D41: =IF(F41=1,$C41,0) -> 0 | E41: =IF(F41=0,C41*$E$29*-1,0) -> 0 | F41: 0 | G41: =IF(F41=1,C41*$E$29*-1,0) -> 0 | H41: =H42+G41 -> -68261.36
D42: =IF(F42=1,$C42,0) -> 0 | E42: =IF(F42=0,C42*$E$29*-1,0) -> 0 | F42: 0 | G42: =IF(F42=1,C42*$E$29*-1,0) -> 0 | H42: =H43+G42 -> -68261.36
D43: =IF(F43=1,$C43,0) -> 0 | E43: =IF(F43=0,C43*$E$29*-1,0) -> 0 | F43: 0 | G43: =IF(F43=1,C43*$E$29*-1,0) -> 0 | H43: =H44+G43 -> -68261.36
D44: =IF(F44=1,$C44,0) -> 0 | E44: =IF(F44=0,C44*$E$29*-1,0) -> 0 | F44: 0 | G44: =IF(F44=1,C44*$E$29*-1,0) -> 0 | H44: =H45+G44 -> -68261.36
D45: =IF(F45=1,$C45,0) -> 0 | E45: =IF(F45=0,C45*$E$29*-1,0) -> 0 | F45: 1 | G45: =IF(F45=1,C45*$E$29*-1,0) -> 0 | H45: =H46+G45 -> -68261.36 | J45: 5
A46: 45660 | B46: snyB bankadan | C46: 290000 | D46: =IF(F46=1,$C46,0) -> 290000 | E46: =IF(F46=0,C46*$E$29*-1,0) -> 0 | F46: 1 | G46: =IF(F46=1,C46*$E$29*-1,0) -> -68261.36 | H46: =G46 -> -68261.36 | J46: 4
J47: ay
C49: Toplam | D49: Hacı | E49: Nazan
...

Sheet NAZAN_24
B2: 2024 YILI NAZAN BALCI
C3: Yapılacak | D3: Kalacak | E3: Yapılan | H3: Kalan
C4: Ödeme | D4: Bakiye | E4: Ödeme | H4: Bakiye
D5: 121030.76 | G5: 2023 yıl sonu nazan kira geliri | H5: =D5 -> 121030.76
G6: 2024 yılı Toplam | H6: =H25*-1 -> 187718.95
H7: =H6+H5 -> 308749.71
A8: 45295 | C8: 10000 | D8: =H7-C8 -> 298749.71 | E8: 10000 | G8: nazan havale | H8: =H7-E8 -> 298749.71
A9: 45323 | C9: 10000 | D9: =D8-C9 -> 288749.71 | E9: 10000 | G9: nazan havale | H9: =H8-E9 -> 288749.71
A10: 45352 | C10: 10000 | D10: =D9-C10 -> 278749.71 | E10: 10000 | G10: nazan havale | H10: =H9-E10 -> 278749.71
A11: 45383 | C11: 10000 | D11: =D10-C11 -> 268749.71 | E11: 10000 | G11: nazan havale | H11: =H10-E11 -> 268749.71
A12: 45413 | C12: 10000 | D12: =D11-C12 -> 258749.71 | E12: 10000 | G12: nazan havale | H12: =H11-E12 -> 258749.71
A13: 45444 | C13: 10000 | D13: =D12-C13 -> 248749.71 | E13: 10000 | G13: nazan havale | H13: =H12-E13 -> 248749.71
A14: 45474 | C14: 10000 | D14: =D13-C14 -> 238749.71 | E14: 10000 | G14: nazan havale | H14: =H13-E14 -> 238749.71
A15: 45505 | C15: 10000 | D15: =D14-C15 -> 228749.71 | F15: ödenmedi | H15: =H14-E15 -> 238749.71
A16: 45536 | C16: 10000 | D16: =D15-C16 -> 218749.71 | F16: ödenmedi | H16: =H15-E16 -> 238749.71
A17: 45566 | C17: 10000 | D17: =D16-C17 -> 208749.71 | F17: ödenmedi | H17: =H16-E17 -> 238749.71
A18: 45623 | B18: snyF | C18: 10000 | D18: =D17-C18 -> 198749.71 | E18: 40000 | H18: =H17-E18 -> 198749.71
A19: 45627 | B19: snyCD | C19: 11030.76 | D19: =D18-C19 -> 187718.95 | E19: 60000 | G19: 2025 e DEVREDEN | H19: =H18-E19 -> 138749.71
D20: TOPLAM ÖDEME | E20: =SUM(E8:E19) -> 170000
B23: Hisse Oranı | D23: 0.764616 | E23: =1-D23 -> 0.235384
A24: Tarih | B24: Açıklama | C24: snyA-H | D24: Oran % | E24: Oran TL Tutar | F24: Ödendi | G24: Oran TL | H24: Genel Toplam | I24: Sütun1
B25: Toplam Gelir | C25: =SUBTOTAL(109,C26:C40) -> 804500.9 | D25: =SUBTOTAL(109,D26:D40) -> 797500.9 | E25: =SUM(E26:E40) -> -1647.688 | G25: =SUBTOTAL(109,$G$26:$G$40) -> -187718.95 | H25: =H26 -> -187718.95
A26: 45656 | B26: snyH- Yazıhane | C26: -3999.1 | D26: =IF(F26=1,$C26,0) -> -3999.1 | E26: =IF(F26=0,C26*$E$23*-1,0) -> 0 | F26: 1 | G26: =IF(F26=1,C26*$E$23*-1,0) -> 941.32415 | H26: =H27+G26 -> -187718.95
D27: =IF(F27=1,$C27,0) -> 0 | E27: =IF(F27=0,C27*$E$23*-1,0) -> 0 | F27: 0 | G27: =IF(F27=1,C27*$E$23*-1,0) -> 0 | H27: =H28+G27 -> -188660.28
D28: =IF(F28=1,$C28,0) -> 0 | E28: =IF(F28=0,C28*$E$23*-1,0) -> 0 | F28: 0 | G28: =IF(F28=1,C28*$E$23*-1,0) -> 0 | H28: =H29+G28 -> -188660.28
A29: 45631 | B29: snyCD-işbank | C29: 219000 | D29: =IF(F29=1,$C29,0) -> 219000 | E29: =IF(F29=0,C29*$E$23*-1,0) -> 0 | F29: 1 | G29: =IF(F29=1,C29*$E$23*-1,0) -> -51549.096 | H29: =H30+G29 -> -188660.28 | I29: 2025 te
A30: 45607 | B30: snyF-icradan | C30: 148500 | D30: =IF(F30=1,$C30,0) -> 148500 | E30: =IF(F30=0,C30*$E$23*-1,0) -> 0 | F30: 1 | G30: =IF(F30=1,C30*$E$23*-1,0) -> -34954.524 | H30: =H31+G30 -> -137111.18
A31: 45405 | B31: snyE- işbanktan | C31: 33000 | D31: =IF(F31=1,$C31,0) -> 33000 | E31: =IF(F31=0,C31*$E$23*-1,0) -> 0 | F31: 1 | G31: =IF(F31=1,C31*$E$23*-1,0) -> -7767.672 | H31: =H32+G31 -> -102156.66
A32: 45405 | B32: snyE- Nakit Slmn | C32: 170000 | D32: =IF(F32=1,$C32,0) -> 170000 | E32: =IF(F32=0,C32*$E$23*-1,0) -> 0 | F32: 1 | G32: =IF(F32=1,C32*$E$23*-1,0) -> -40015.28 | H32: =H33+G32 -> -94388.984
A33: 45405 | B33: snyE İADE Chn | C33: -25000 | D33: =IF(F33=1,$C33,0) -> -25000 | E33: =IF(F33=0,C33*$E$23*-1,0) -> 0 | F33: 1 | G33: =IF(F33=1,C33*$E$23*-1,0) -> 5884.6 | H33: =H34+G33 -> -54373.704
A34: 45397 | B34: snyE Nakit Slmn | C34: 1000 | D34: =IF(F34=1,$C34,0) -> 1000 | E34: =IF(F34=0,C34*$E$23*-1,0) -> 0 | F34: 1 | G34: =IF(F34=1,C34*$E$23*-1,0) -> -235.384 | H34: =H35+G34 -> -60258.304
A35: 45397 | B35: snyF-işbanktan | C35: 85000 | D35: =IF(F35=1,$C35,0) -> 85000 | E35: =IF(F35=0,C35*$E$23*-1,0) -> 0 | F35: 1 | G35: =IF(F35=1,C35*$E$23*-1,0) -> -20007.64 | H35: =H36+G35 -> -60022.92
A36: 45321 | B36: SnyE- Nakit->nazana | C36: 7000 | D36: =IF(F36=1,$C36,0) -> 0 | E36: =IF(F36=0,C36*$E$23*-1,0) -> -1647.688 | F36: 0 | G36: =IF(F36=1,C36*$E$23*-1,0) -> 0 | H36: =H37+G36 -> -40015.28
B37: snyB- bankadan | C37: 24000 | D37: =IF(F37=1,$C37,0) -> 24000 | E37: =IF(F37=0,C37*$E$23*-1,0) -> 0 | F37: 1 | G37: =IF(F37=1,C37*$E$23*-1,0) -> -5649.216 | H37: =H38+G37 -> -40015.28
A38: 45296 | B38: snyB- nakit | C38: 26000 | D38: =IF(F38=1,$C38,0) -> 26000 | E38: =IF(F38=0,C38*$E$23*-1,0) -> 0 | F38: 1 | G38: =IF(F38=1,C38*$E$23*-1,0) -> -6119.984 | H38: =H39+G38 -> -34366.064
A39: 45295 | B39: snyB- nakit | C39: 120000 | D39: =IF(F39=1,$C39,0) -> 120000 | E39: =IF(F39=0,C39*$E$23*-1,0) -> 0 | F39: 1 | G39: =IF(F39=1,C39*$E$23*-1,0) -> -28246.08 | H39: =H40+G39 -> -28246.08
A40: 45292 | B40: snyF | D40: =IF(F40=1,$C40,0) -> 0 | E40: =IF(F40=0,C40*$E$23*-1,0) -> 0 | F40: 0 | G40: =IF(F40=1,C40*$E$23*-1,0) -> 0 | H40: =G40 -> 0
C43: Toplam | D43: Hacı | E43: Nazan
B44: % | C44: 1 | D44: =D23 -> 0.764616 | E44: =1-D44 -> 0.235384
B45: Toplam Gelecek | C45: =$D$25*C44 -> 797500.9 | D45: =$D$25*D44 -> 609781.95 | E45: =$D$25*E44 -> 187718.95
...
